Watching for file changes with StatReloader
Exception in thread django-main-thread:
Traceback (most recent call last):
  File "C:\Users\UBANDK2\AppData\Local\Programs\Python\Python310\lib\threading.py", line 1016, in _bootstrap_inner
    self.run()
  File "C:\Users\UBANDK2\AppData\Local\Programs\Python\Python310\lib\threading.py", line 953, in run
    self._target(*self._args, **self._kwargs)
  File "C:\Users\UBANDK2\AppData\Local\Programs\Python\Python310\lib\site-packages\django\utils\autoreload.py", line 64, in wrapper
    fn(*args, **kwargs)
  File "C:\Users\UBANDK2\AppData\Local\Programs\Python\Python310\lib\site-packages\django\core\management\commands\runserver.py", line 133, in inner_run
    self.check(display_num_errors=True)
  File "C:\Users\UBANDK2\AppData\Local\Programs\Python\Python310\lib\site-packages\django\core\management\base.py", line 485, in check
    all_issues = checks.run_checks(
  File "C:\Users\UBANDK2\AppData\Local\Programs\Python\Python310\lib\site-packages\django\core\checks\registry.py", line 88, in run_checks
    new_errors = check(app_configs=app_configs, databases=databases)
  File "C:\Users\UBANDK2\AppData\Local\Programs\Python\Python310\lib\site-packages\django\core\checks\urls.py", line 14, in check_url_config
    return check_resolver(resolver)
  File "C:\Users\UBANDK2\AppData\Local\Programs\Python\Python310\lib\site-packages\django\core\checks\urls.py", line 24, in check_resolver
    return check_method()
  File "C:\Users\UBANDK2\AppData\Local\Programs\Python\Python310\lib\site-packages\django\urls\resolvers.py", line 494, in check
    for pattern in self.url_patterns:
  File "C:\Users\UBANDK2\AppData\Local\Programs\Python\Python310\lib\site-packages\django\utils\functional.py", line 57, in __get__
    res = instance.__dict__[self.name] = self.func(instance)
  File "C:\Users\UBANDK2\AppData\Local\Programs\Python\Python310\lib\site-packages\django\urls\resolvers.py", line 715, in url_patterns
    patterns = getattr(self.urlconf_module, "urlpatterns", self.urlconf_module)
  File "C:\Users\UBANDK2\AppData\Local\Programs\Python\Python310\lib\site-packages\django\utils\functional.py", line 57, in __get__
    res = instance.__dict__[self.name] = self.func(instance)
  File "C:\Users\UBANDK2\AppData\Local\Programs\Python\Python310\lib\site-packages\django\urls\resolvers.py", line 708, in urlconf_module
    return import_module(self.urlconf_name)
  File "C:\Users\UBANDK2\AppData\Local\Programs\Python\Python310\lib\importlib\__init__.py", line 126, in import_module
    return _bootstrap._gcd_import(name[level:], package, level)
  File "<frozen importlib._bootstrap>", line 1050, in _gcd_import
  File "<frozen importlib._bootstrap>", line 1027, in _find_and_load
  File "<frozen importlib._bootstrap>", line 1006, in _find_and_load_unlocked
  File "<frozen importlib._bootstrap>", line 688, in _load_unlocked
  File "<frozen importlib._bootstrap_external>", line 883, in exec_module
  File "<frozen importlib._bootstrap>", line 241, in _call_with_frames_removed
  File "C:\face_auth\staff_auth_app\staff_auth_app\urls.py", line 3, in <module>
    from authentication import views 
  File "C:\face_auth\staff_auth_app\authentication\views.py", line 9, in <module>
    from dateutil.parser import parse
ModuleNotFoundError: No module named 'dateutil'
^C